<?xml version="1.0"?>
<robot name="visual">

  <link name="world"/>

  <link name="rh_palm"/>

  <!-- THUMB -->

  <!-- World to the first link -->
  <joint name="world_to_palm" type="fixed">
    <parent link="world"/>
    <child link="rh_palm"/>
    <origin xyz="0 0 0" rpy="0.0 -1.57079632679 3.14159265359"/>
  </joint>

  <!-- METACARPAL: fixed joints starting from common reference -->
  <link name="rh_thmetacarpal">
  </link>

  <joint name="palm_to_thmetacarpal" type="fixed">
    <parent link="rh_palm"/>
    <child link="rh_thmetacarpal"/>
    <origin xyz="0.0 0.073 0.0842" rpy="0.5686 -1.5355 0.4044"/>
  </joint>

  <!-- CMC (2 DOF) joint thumb -->
  <link name="rh_thcmc1">
  </link>

  <joint name="thmetacarpal_to_thcmc1" type="revolute">
    <parent link="rh_thmetacarpal"/>
    <child link="rh_thcmc1"/>
    <origin xyz="0.0 0.0 0.0" rpy="0.0 0.0 0.0"/>
    <limit lower="-0.5235987756" upper="1.047197551" effort="1000.0" velocity="0.5"/>
  </joint>

  <link name="rh_thcmc2">
  </link>

  <joint name="thcmc1_to_thcmc2" type="revolute">
    <parent link="rh_thcmc1"/>
    <child link="rh_thcmc2"/>
    <origin xyz="0.0 0.0 0.0" rpy="0.0 0.0 0.0"/>
    <axis xyz="0 0 1"/>
    <limit lower="-0.436332313" upper="0.6108652382" effort="1000.0" velocity="0.5"/>
  </joint>

  <!-- Thumb proximal phalanx MPC (2DOF) -->
  <link name="rh_thproximalphalanx">
  </link>

  <joint name="thcmc2_to_thproximalphalanx" type="revolute">
    <parent link="rh_thcmc2"/>
    <child link="rh_thproximalphalanx"/>
    <origin xyz="0.0 0.251 0.0" rpy="0.0 0.0 0.0"/>
    <axis xyz="0 0 1"/>
    <limit lower="-0.5235987756" upper="1.047197551" effort="1000.0" velocity="0.5"/>
  </joint>

  <link name="rh_thmpc">
  </link>

  <joint name="thproximalphalanx_to_thmpc" type="revolute">
    <parent link="rh_thproximalphalanx"/>
    <child link="rh_thmpc"/>
    <origin xyz="0.0 0.0 0.0" rpy="0.0 0.0 0.0"/>
    <axis xyz="1 0 0"/>
    <limit lower="-0.1745329252" upper="1.396263402" effort="1000.0" velocity="0.5"/>
  </joint>

  <!-- Thumb medial phalanx MPC (1DOF) -->
  <link name="rh_thmedialphalanx">
  </link>

  <joint name="thmpc_to_thmedialphalanx" type="revolute">
    <parent link="rh_thmpc"/>
    <child link="rh_thmedialphalanx"/>
    <origin xyz="0.0 0.196 0.0" rpy="0.0 0.0 0.0"/>
    <axis xyz="0 0 1"/>
    <limit lower="-0.2617993878" upper="1.396263402" effort="1000.0" velocity="0.5"/>
  </joint>

  <link name="rh_thdistalphalanx">
  </link>

  <joint name="thmedialphalanx_to_thdistalphalanx" type="fixed">
    <parent link="rh_thmedialphalanx"/>
    <child link="rh_thdistalphalanx"/>
    <origin xyz="0.0 0.158 0.0" rpy="0.0 0.0 0.0"/>
  </joint>

  <link name="rh_thtip">
  </link>

  <joint name="thdistalphalanx_to_thtip" type="fixed">
    <parent link="rh_thdistalphalanx"/>
    <child link="rh_thtip"/>
    <origin xyz="0.0 0.0 0.0" rpy="0.0 0.0 0.0"/>
  </joint>

  <!-- FIRST FINGER -->

  <link name="rh_ffmetacarpal">
  </link>

  <joint name="palm_to_ffmetacarpal" type="fixed">
    <parent link="rh_palm"/>
    <child link="rh_ffmetacarpal"/>
    <origin xyz="0.0 0.073 0.0541" rpy="0.1438 0.0 0.0"/>
  </joint>

  <link name="rh_ffproximalphalanx">
  </link>

  <joint name="ffmetacarpal_to_ffproximalphalanx" type="fixed">
    <parent link="rh_ffmetacarpal"/>
    <child link="rh_ffproximalphalanx"/>
    <origin xyz="0.0 0.3779 0.0" rpy="-0.2618 0.0 0.0"/>
  </joint>

  <!-- First Finger MPC (2DOF) -->
  <link name="rh_ffmpc1">
  </link>

  <joint name="ffmetacarpal_to_ffmpc1" type="revolute">
    <parent link="rh_ffproximalphalanx"/>
    <child link="rh_ffmpc1"/>
    <origin xyz="0.0 0.0 0.0" rpy="0.0 0.0 0.0"/>
    <axis xyz="1 0 0"/>
    <limit lower="-0.2617993878" upper="0.7330382858" effort="1000.0" velocity="0.5"/>
  </joint>

  <link name="rh_ffmpc2">
  </link>

  <joint name="ffmpc1_to_ffmpc2" type="revolute">
    <parent link="rh_ffmpc1"/>
    <child link="rh_ffmpc2"/>
    <origin xyz="0.0 0.0 0.0" rpy="0.0 0.0 0.0"/>
    <axis xyz="0 0 1"/>
    <limit lower="0.0" upper="1.570796327" effort="1000.0" velocity="0.5"/>
  </joint>

  <link name="rh_ffmedialphalanx">
  </link>

  <joint name="ffmpc2_to_ffmedialphalanx" type="revolute">
    <parent link="rh_ffmpc2"/>
    <child link="rh_ffmedialphalanx"/>
    <origin xyz="0.0 0.2649 0.0" rpy="0.0 0.0 0.0"/>
    <axis xyz="0 0 1"/>
    <limit lower="0.0" upper="1.745329252" effort="1000.0" velocity="0.5"/>
  </joint>

  <link name="rh_ffdistalphalanx">
  </link>

  <joint name="ffmedialphalanx_to_ffdistalphalanx" type="revolute">
    <parent link="rh_ffmedialphalanx"/>
    <child link="rh_ffdistalphalanx"/>
    <origin xyz="0.0 0.143 0.0" rpy="0.0 0.0 0.0"/>
    <axis xyz="0 0 1"/>
    <limit lower="0.0" upper="1.570796327" effort="1000.0" velocity="0.5"/>
  </joint>

  <link name="rh_fftip">
  </link>

  <joint name="ffdistalphalanx_to_fftip" type="fixed">
    <parent link="rh_ffdistalphalanx"/>
    <child link="rh_fftip"/>
    <origin xyz="0.0 0.097 0.0" rpy="0.0 0.0 0.0"/>
  </joint>

  <!-- MIDDLE FINGER -->

  <link name="rh_mfmetacarpal">
  </link>

  <joint name="palm_to_mfmetacarpal" type="fixed">
    <parent link="rh_palm"/>
    <child link="rh_mfmetacarpal"/>
    <origin xyz="0.0 0.073 0.0" rpy="0.0 0.0 0.0"/>
  </joint>

  <link name="rh_mfproximalphalanx">
  </link>

  <joint name="mfmetacarpal_to_mfproximalphalanx" type="fixed">
    <parent link="rh_mfmetacarpal"/>
    <child link="rh_mfproximalphalanx"/>
    <origin xyz="0.0 0.377 0.0" rpy="-0.1047 0.0 0.0"/>
  </joint>


  <!-- Middle Finger MPC (2DOF) -->
  <link name="rh_mfmpc1">
  </link>

  <joint name="mfmetacarpal_to_mfmpc1" type="revolute">
    <parent link="rh_mfproximalphalanx"/>
    <child link="rh_mfmpc1"/>
    <origin xyz="0.0 0.0 0.0" rpy="0.0 0.0 0.0"/>
    <axis xyz="1 0 0"/>
    <limit lower="-0.1396263402" upper="0.6108652382" effort="1000.0" velocity="0.5"/>
  </joint>

  <link name="rh_mfmpc2">
  </link>

  <joint name="mfmpc1_to_mfmpc2" type="revolute">
    <parent link="rh_mfmpc1"/>
    <child link="rh_mfmpc2"/>
    <origin xyz="0.0 0.0 0.0" rpy="0.0 0.0 0.0"/>
    <axis xyz="0 0 1"/>
    <limit lower="0.0" upper="1.570796327" effort="1000.0" velocity="0.5"/>
  </joint>

  <link name="rh_mfmedialphalanx">
  </link>

  <joint name="mfmpc2_to_mfmedialphalanx" type="revolute">
    <parent link="rh_mfmpc2"/>
    <child link="rh_mfmedialphalanx"/>
    <origin xyz="0.0 0.2773 0.0" rpy="0.0 0.0 0.0"/>
    <axis xyz="0 0 1"/>
    <limit lower="0.0" upper="1.745329252" effort="1000.0" velocity="0.5"/>
  </joint>

  <link name="rh_mfdistalphalanx">
  </link>

  <joint name="mfmedialphalanx_to_mfdistalphalanx" type="revolute">
    <parent link="rh_mfmedialphalanx"/>
    <child link="rh_mfdistalphalanx"/>
    <origin xyz="0.0 0.17 0.0" rpy="0.0 0.0 0.0"/>
    <axis xyz="0 0 1"/>
    <limit lower="0.0" upper="1.570796327" effort="1000.0" velocity="0.5"/>
  </joint>

  <link name="rh_mftip">
  </link>

  <joint name="mfdistalphalanx_to_mftip" type="fixed">
    <parent link="rh_mfdistalphalanx"/>
    <child link="rh_mftip"/>
    <origin xyz="0.0 0.108 0.0" rpy="0.0 0.0 0.0"/>
  </joint>

  <!-- RING FINGER -->

  <link name="rh_rfmetacarpal">
  </link>

  <joint name="palm_to_rfmetacarpal" type="fixed">
    <parent link="rh_palm"/>
    <child link="rh_rfmetacarpal"/>
    <origin xyz="0.0 0.073 -0.0554" rpy="-0.0981 0.0 0.0"/>
  </joint>

  <link name="rh_rfcmc">
  </link>

  <joint name="rfmetacarpal_to_rfcmc" type="revolute">
    <parent link="rh_rfmetacarpal"/>
    <child link="rh_rfcmc"/>
    <origin xyz="0.0 0.0 0.0" rpy="0.0 0.0 0.0"/>
    <axis xyz="0 1 0"/>
    <limit lower="0.0" upper="0.2617993878" effort="1000.0" velocity="0.5"/>
  </joint>

  <link name="rh_rfproximalphalanx">
  </link>

  <joint name="rfmetacarpal_to_rfproximalphalanx" type="fixed">
    <parent link="rh_rfcmc"/>
    <child link="rh_rfproximalphalanx"/>
    <origin xyz="0.0 0.3376 0.0" rpy="0.0 0.0 0.0"/>
  </joint>

  <!-- Ring Finger MPC (2DOF) -->
  <link name="rh_rfmpc1">
  </link>

  <joint name="rfmetacarpal_to_rfmpc1" type="revolute">
    <parent link="rh_rfproximalphalanx"/>
    <child link="rh_rfmpc1"/>
    <origin xyz="0.0 0.0 0.0" rpy="0.0 0.0 0.0"/>
    <axis xyz="1 0 0"/>
    <limit lower="-0.3490658504" upper="0.2443460953" effort="1000.0" velocity="0.5"/>
  </joint>

  <link name="rh_rfmpc2">
  </link>

  <joint name="rfmpc1_to_rfmpc2" type="revolute">
    <parent link="rh_rfmpc1"/>
    <child link="rh_rfmpc2"/>
    <origin xyz="0.0 0.0 0.0" rpy="0.0 0.0 0.0"/>
    <axis xyz="0 0 1"/>
    <limit lower="0.0" upper="1.570796327" effort="1000.0" velocity="0.5"/>
  </joint>

  <link name="rh_rfmedialphalanx">
  </link>

  <joint name="rfmpc2_to_rfmedialphalanx" type="revolute">
    <parent link="rh_rfmpc2"/>
    <child link="rh_rfmedialphalanx"/>
    <origin xyz="0.0 0.2591 0.0" rpy="0.0 0.0 0.0"/>
    <axis xyz="0 0 1"/>
    <limit lower="0.0" upper="1.745329252" effort="1000.0" velocity="0.5"/>
  </joint>

  <link name="rh_rfdistalphalanx">
  </link>

  <joint name="rfmedialphalanx_to_rfdistalphalanx" type="revolute">
    <parent link="rh_rfmedialphalanx"/>
    <child link="rh_rfdistalphalanx"/>
    <origin xyz="0.0 0.165 0.0" rpy="0.0 0.0 0.0"/>
    <axis xyz="0 0 1"/>
    <limit lower="0.0" upper="1.570796327" effort="1000.0" velocity="0.5"/>
  </joint>

  <link name="rh_rftip">
  </link>

  <joint name="rfdistalphalanx_to_rftip" type="fixed">
    <parent link="rh_rfdistalphalanx"/>
    <child link="rh_rftip"/>
    <origin xyz="0.0 0.107 0.0" rpy="0.0 0.0 0.0"/>
  </joint>

  <!-- LITTLE FINGER -->

  <link name="rh_lfmetacarpal">
  </link>

  <joint name="palm_to_lfmetacarpal" type="fixed">
    <parent link="rh_palm"/>
    <child link="rh_lfmetacarpal"/>
    <origin xyz="0.0 0.073 -0.0958" rpy="-0.2427 0.0 0.0"/>
  </joint>

  <link name="rh_lfcmc">
  </link>

  <joint name="rfmetacarpal_to_lfcmc" type="revolute">
    <parent link="rh_lfmetacarpal"/>
    <child link="rh_lfcmc"/>
    <origin xyz="0.0 0.0 0.0" rpy="0.0 0.0 0.0"/>
    <axis xyz="0 1 0"/>
    <limit lower="0.0" upper="0.5235987756" effort="1000.0" velocity="0.5"/>
  </joint>

  <link name="rh_lfproximalphalanx">
  </link>

  <joint name="lfmetacarpal_to_lfproximalphalanx" type="fixed">
    <parent link="rh_lfcmc"/>
    <child link="rh_lfproximalphalanx"/>
    <origin xyz="0.0 0.3049 0.0" rpy="0.1222 0.0 0.0"/>
  </joint>

  <!-- Little Finger MPC (2DOF) -->
  <link name="rh_lfmpc1">
  </link>

  <joint name="lfmetacarpal_to_lfmpc1" type="revolute">
    <parent link="rh_lfproximalphalanx"/>
    <child link="rh_lfmpc1"/>
    <origin xyz="0.0 0.0 0.0" rpy="0.0 0.0 0.0"/>
    <axis xyz="1 0 0"/>
    <limit lower="-0.6981317008" upper="0.3316125579" effort="1000.0" velocity="0.5"/>
  </joint>

  <link name="rh_lfmpc2">
  </link>

  <joint name="lfmpc1_to_lfmpc2" type="revolute">
    <parent link="rh_lfmpc1"/>
    <child link="rh_lfmpc2"/>
    <origin xyz="0.0 0.0 0.0" rpy="0.0 0.0 0.0"/>
    <axis xyz="0 0 1"/>
    <limit lower="0.0" upper="1.570796327" effort="1000.0" velocity="0.5"/>
  </joint>

  <link name="rh_lfmedialphalanx">
  </link>

  <joint name="lfmpc2_to_lfmedialphalanx" type="revolute">
    <parent link="rh_lfmpc2"/>
    <child link="rh_lfmedialphalanx"/>
    <origin xyz="0.0 0.2059 0.0" rpy="0.0 0.0 0.0"/>
    <axis xyz="0 0 1"/>
    <limit lower="0.0" upper="1.745329252" effort="1000.0" velocity="0.5"/>
  </joint>

  <link name="rh_lfdistalphalanx">
  </link>

  <joint name="lfmedialphalanx_to_lfdistalphalanx" type="revolute">
    <parent link="rh_lfmedialphalanx"/>
    <child link="rh_lfdistalphalanx"/>
    <origin xyz="0.0 0.117 0.0" rpy="0.0 0.0 0.0"/>
    <axis xyz="0 0 1"/>
    <limit lower="0.0" upper="1.570796327" effort="1000.0" velocity="0.5"/>
  </joint>

  <link name="rh_lftip">
  </link>

  <joint name="lfdistalphalanx_to_rftip" type="fixed">
    <parent link="rh_lfdistalphalanx"/>
    <child link="rh_lftip"/>
    <origin xyz="0.0 0.093 0.0" rpy="0.0 0.0 0.0"/>
  </joint>

</robot>